Modbus

INSTALLED VERSIONS

commit: None

python: 3.6.6.final.0

python-bits: 64

OS: Darwin

OS-release: 18.5.0

machine: x86_64

processor: i386

byteorder: little

LC_ALL: None

LANG: en_US.UTF-8

LOCALE: en_US.UTF-8

pandas: 0.24.2

pytest: 3.9.1

pip: 19.0.3

setuptools: 40.2.0

Cython: None

numpy: 1.16.3

scipy: 1.1.0

pyarrow: 0.13.0

xarray: None

IPython: 6.5.0

sphinx: None

patsy: 0.5.1

dateutil: 2.7.3

pytz: 2018.5

blosc: None

bottleneck: None

tables: 3.5.1

numexpr: 2.6.9

feather: None

matplotlib: 2.2.3

openpyxl: None

xlrd: 1.1.0

xlwt: None

xlsxwriter: 1.1.2

lxml.etree: None

bs4: None

html5lib: 1.0.1

sqlalchemy: None

pymysql: None

psycopg2: None

jinja2: 2.10

s3fs: None

fastparquet: None

pandas_gbq: None

pandas_datareader: None

gcsfs: None

apt

`tasks/main.yml`:

`defaults/main.yml`:

    dedicated-build.qemu.ubuntu-dedicated:     "stdout": "Reading package lists...\nBuilding dependency tree...\nReading state information...\nThe following packages will be REMOVED:\n  accountsservice* eject* file* gir1.2-packagekitglib-1.0*\n  grub-efi-amd64-signed* iso-codes* krb5-locales* language-selector-common*\n  libaccountsservice0* libappstream4* libdw1* libglib2.0-bin*\n  libgstreamer1.0-0* libmagic-mgc* libmagic1* libntfs-3g883*\n  libpackagekit-glib2-18* libstemmer0d* libx11-6* libx11-data* libxau6*\n  libxcb1* libxdmcp6* libxext6* libxmuu1* mokutil* ntfs-3g* packagekit*\n  packagekit-tools* python3-software-properties* shim-signed* snapd*\n  software-properties-common* squashfs-tools* telnet* ubuntu-minimal*\n  ubuntu-server* ubuntu-standard* unattended-upgrades* xauth*\nWARNING: The following essential packages will be removed.\nThis should NOT be done unless you know exactly what you are doing!\n  shim-signed grub-efi-amd64-signed (due to shim-signed)\n  mokutil (due to shim-signed)\n0 upgraded, 0 newly installed, 40 to remove and 0 not upgraded.\nAfter this operation, 149 MB disk space will be freed.\nW: --force-yes is deprecated, use one of the options starting with --allow instead.\nYou are about to do something potentially harmful.\nTo continue type in the phrase 'Yes, do as I say!'\n ?] ",

plugins/connection/ssh.py

transfer_method = smart

test.yml

wolverine

**Description of problem:**

After upgrade to version 0.21.0, initially Home Assistant seems to function, but when requesting the History, this will result a call to `/api/history/period/2016-6-11`, returning a 500 error with content:

  File "/home/pi/.homeassistant/deps/werkzeug/wsgi.py", line 659, in **call**

Yaml does not seem relevant

1. Wink

2. IFTTT

3. LIFX

configured module search path = [u'/home/ryan/.ansible/plugins/modules', u'/usr/share/ansible/plugins/modules']

"ERROR! need more than 2 values to unpack"

[test group]

(venv) airflow dags test docker_sample now

INSTALLED VERSIONS

commit: None

python: 2.7.12.final.0

python-bits: 64

OS: Linux

OS-release: 2.6.32-573.22.1.el6.x86_64

machine: x86_64

processor: x86_64

byteorder: little

LC_ALL: None

LANG: en_US.UTF-8

pandas: 0.18.1

nose: 1.3.4

pip: 8.1.2

setuptools: 23.0.0

Cython: 0.21

numpy: 1.10.2

scipy: 0.15.1

statsmodels: 0.6.1

xarray: None

IPython: 4.0.0

sphinx: 1.2.3

patsy: 0.3.0

dateutil: 2.5.3

pytz: 2016.6.1

blosc: None

bottleneck: None

tables: 3.2.2

numexpr: 2.4.4

matplotlib: 1.4.3

openpyxl: 2.3.2

xlrd: 0.9.3

xlwt: 0.7.5

xlsxwriter: 0.5.7

lxml: 3.4.0

bs4: 4.3.2

html5lib: None

httplib2: None

apiclient: None

sqlalchemy: 0.9.7

pymysql: None

psycopg2: None

jinja2: 2.8

boto: 2.32.1

pandas_datareader: None

history:

ssdp:

sensor: !include sensors.yaml

Invalid type for parameter AuthParameters.REFRESH_TOKEN, value: None, type: <class 'NoneType'>, valid types: <class 'str'>

Invalid type for parameter AuthParameters.REFRESH_TOKEN, value: None, type: <class 'NoneType'>, valid types: <class 'str'>

aws_ec2

plugin: aws_ec2

hostnames:

  - instance-id

nothing output

Logger: homeassistant.components.switch

  - service: modbus.write_register

when I use this, it not working and in cmd show

  File "mnistTest.py", line 7, in <module>

fetch_mldata

se the connected party did not properly respond after a period of time, or estab

Source: /usr/local/lib/python3.9/site-packages/homeconnect/sseclient.py:89

Exception while reading event:

StopIteration

Source: /usr/local/lib/python3.9/site-packages/homeconnect/sseclient.py:89

Exception while reading event:

StopIteration

* Python version: 3.7.4

* Flask version: 1.1.1

* Werkzeug version: 0.16.0

2.2.0 (latest released)

apache-airflow-providers-celery==2.1.0

apache-airflow-providers-mysql==2.1.1

apache-airflow-providers-postgres==2.3.0

apache-airflow-providers-sqlite==2.0.1

volumes:

Dockerfile:

requirements.txt:

python-dotenv

psycopg2-binary

~/airflow $ docker-compose up -d --force

~/airflow $ docker exec -it airflow_airflow-webserver_1 airflow db upgrade

DB: mysql://airflow:***@airflow-celery/airflow

INFO  [alembic.runtime.migration] Will assume non-transactional DDL.

INFO  [alembic.runtime.migration] Running upgrade 142555e44c17 -> 7b2661a43ba3, TaskInstance keyed to DagRun

  File "/usr/local/lib/python3.8/site-packages/sqlalchemy/util/compat.py", line 182, in raise_

ansible-liferay-nginx/vars/main.yml

proxmox (https://github.com/mrdrogdrog/ansible/blob/6430205d396b7c1733de22a898c51823f67d5bf4/lib/ansible/modules/cloud/misc/proxmox.py#L484)

dconf

  when: ansible_os_family == 'RedHat'

ec2_vpc_endpoint

X-Forwarded-For: client, proxy1, proxy2

(5 additional frame(s) were not displayed)

Using Enhanced Data Generation

Error setting up platform legacy

letsencrypt.py

INSTALLED VERSIONS

commit: None

python: 2.7.11.final.0

python-bits: 64

OS: Darwin

OS-release: 15.6.0

machine: x86_64

processor: i386

byteorder: little

LC_ALL: None

LANG: en_US.UTF-8

pandas: 0.18.1

nose: None

pip: 8.1.2

setuptools: 25.1.4

Cython: None

numpy: 1.11.1

scipy: None

statsmodels: None

xarray: None

IPython: None

sphinx: None

patsy: None

dateutil: 2.5.3

pytz: 2016.6.1

blosc: None

bottleneck: None

tables: None

numexpr: None

matplotlib: None

openpyxl: None

xlrd: None

xlwt: None

xlsxwriter: None

lxml: None

bs4: None

html5lib: None

httplib2: None

apiclient: None

sqlalchemy: None

pymysql: None

psycopg2: None

jinja2: None

boto: None

pandas_datareader: None

INSTALLED VERSIONS

commit: None

python: 3.6.5.final.0

python-bits: 64

OS: Linux

OS-release: 4.14.39-calculate

machine: x86_64

processor: Intel(R) Core(TM) i5-7200U CPU @ 2.50GHz

byteorder: little

LC_ALL: None

LANG: ru_RU.utf8

LOCALE: ru_RU.UTF-8

pandas: 0.23.0

pytest: None

pip: 9.0.3

setuptools: 39.0.1

Cython: None

numpy: 1.14.3

scipy: 1.1.0

pyarrow: None

xarray: None

IPython: 6.4.0

sphinx: None

patsy: 0.5.0

dateutil: 2.7.3

pytz: 2018.4

blosc: None

bottleneck: None

tables: None

numexpr: None

feather: None

matplotlib: 2.2.2

openpyxl: None

xlrd: None

xlwt: None

xlsxwriter: None

lxml: None

bs4: 4.6.0

html5lib: 0.9999999

sqlalchemy: None

pymysql: None

psycopg2: None

jinja2: 2.10

s3fs: None

fastparquet: None

pandas_gbq: None

pandas_datareader: None

thefuck_contrib_foo

https://github.com/numpy/numpy/blob/master/doc/source/dev/development_environment.rst#debugging -->

SELINUX= disabled

Python 3.3.5

Logger: homeassistant.components.mqtt

Integration: MQTT (documentation, issues)

  File "<ipython-input-6-db63d61cf602>", line 1, in <module>

  AttributeError: 'HTTPAdapter' object has no attribute 'proxy_manager'

Using list:  0.6015908718109131

Using numpy array:  0.895500898361206

Email was sent successfully. But the following exception is thrown;

- role: ansible-role-service-account

arch | x86_64

dev | false

docker | true

hassio | false

installation_type | Home Assistant Container

os_name | Linux

os_version | 4.4.59+

python_version | 3.8.5

timezone | Europe/Rome

version | 0.116.2

virtualenv | false

***** Running training *****

  File "/home/ines/NN_pruning/venv_nn_prun/lib/python3.7/site-packages/transformers/trainer.py", line 1542, in training_step

INSTALLED VERSIONS

commit: 0d8e7c976b8e39e1a32053b6e4382fbb5cbe5c3a

python: 3.6.4.final.0

python-bits: 64

OS: Darwin

OS-release: 17.4.0

machine: x86_64

processor: i386

byteorder: little

LC_ALL: None

LANG: en_GB.UTF-8

LOCALE: en_GB.UTF-8

pandas: 0.24.0.dev0+32.g0d8e7c976

pytest: 3.6.0

pip: 10.0.1

setuptools: 39.2.0

Cython: 0.28.2

numpy: 1.14.3

scipy: 1.1.0

pyarrow: 0.9.0.post1

xarray: 0.10.4

IPython: 6.4.0

sphinx: 1.7.4

patsy: None

dateutil: 2.7.3

pytz: 2018.4

blosc: 1.5.1

bottleneck: 1.2.1

tables: 3.4.3

numexpr: 2.6.5

feather: 0.4.0

matplotlib: 2.2.2

openpyxl: 2.5.3

xlrd: 1.1.0

xlwt: 1.3.0

xlsxwriter: 1.0.5

lxml: 4.2.1

bs4: 4.6.0

html5lib: 1.0.1

sqlalchemy: 1.2.7

pymysql: 0.8.1

psycopg2: None

jinja2: 2.10

s3fs: 0.1.5

fastparquet: 0.1.5

pandas_gbq: None

pandas_datareader: None

[9:45am] erikcw: Is it possible to override settings.URL_FIELD_NAME on a per view/serializer basis?

[3:14pm] erikcw: Any idea if a pull request would be accepted for this?

[3:16pm] linovia: erikcw: dunno. It looks like it would make the hyperlinked serializers inconsistent

[3:18pm] erikcw: My use case is that I have 2 APIs in a django project.  A legacy tastypie API that has been migrated to DRF (and hence uses the setting to turn “url” into “resource_uri”).  I also have an “admin” API that sticks to the standard DRF style

[3:20pm] linovia: erikcw: then I think the way to go would be to bring that to an issue so we can discuss it further before putting work in it

Error setting up entry ShellyPlus1PM-A8032ABE140C for shelly

  File "/usr/local/lib/python3.9/site-packages/aioshelly/rpc_device.py", line 93, in initialize

gcp_compute_instance_facts

None

  platform: tuya

File "/usr/src/homeassistant/homeassistant/components/tuya/light.py", line 43, in brightness

  File "/usr/local/lib/python3.7/site-packages/tuyaha/devices/light.py", line 16, in brightness

  File "/usr/local/lib/python2.7/dist-packages/netlib-0.13.1-py2.7.egg/netlib/version_check.py", line 32, in version_check

TypeError: Series.name must be a hashable type

TypeError: Series.name must be a hashable type

[#18930](https://github.com/pandas-dev/pandas/issues/18930)

INSTALLED VERSIONS

commit           : f00ed8f47020034e752baf0250483053340971b0

python           : 3.9.6.final.0

python-bits      : 64

OS               : Linux

OS-release       : 5.13.5-1-MANJARO

Version          : #1 SMP PREEMPT Mon Jul 26 07:43:29 UTC 2021

machine          : x86_64

processor        :

byteorder        : little

LC_ALL           : None

LANG             : en_US.utf8

LOCALE           : en_US.UTF-8

pandas           : 1.3.0

numpy            : 1.20.3

pytz             : 2021.1

dateutil         : 2.8.2

pip              : 21.2.2

setuptools       : 52.0.0.post20210125

Cython           : None

pytest           : None

hypothesis       : None

sphinx           : None

blosc            : None

feather          : None

xlsxwriter       : None

lxml.etree       : None

html5lib         : None

pymysql          : None

psycopg2         : None

jinja2           : 3.0.1

IPython          : 7.26.0

pandas_datareader: None

bs4              : None

bottleneck       : 1.3.2

fsspec           : 2021.07.0

fastparquet      : None

gcsfs            : None

matplotlib       : None

numexpr          : 2.7.3

odfpy            : None

openpyxl         : None

pandas_gbq       : None

pyarrow          : None

pyxlsb           : None

s3fs             : None

scipy            : 1.7.0

sqlalchemy       : None

tables           : None

tabulate         : None

xarray           : 0.19.0

xlrd             : None

xlwt             : None

numba            : 0.53.1

Function call stack:

distributed_prediction_steps

e - ascending

e - descending

f - ascending

f - descending

f - ascending

f - descending

e - ascending

INSTALLED VERSIONS

commit: None

python: 3.6.1.final.0

python-bits: 64

OS: Darwin

OS-release: 15.6.0

machine: x86_64

processor: i386

byteorder: little

LC_ALL: None

LANG: en_US.UTF-8

LOCALE: en_US.UTF-8

pandas: 0.21.0rc1

pytest: 3.0.7

pip: 9.0.1

setuptools: 35.0.2

Cython: 0.25.2

numpy: 1.13.3

scipy: 0.19.0

pyarrow: None

xarray: None

IPython: 6.0.0

sphinx: 1.5.5

patsy: 0.4.1

dateutil: 2.6.1

pytz: 2017.2

blosc: None

bottleneck: 1.2.0

tables: 3.4.2

numexpr: 2.6.2

feather: None

matplotlib: 2.1.0

openpyxl: 2.4.7

xlrd: 1.0.0

xlwt: 1.2.0

xlsxwriter: 0.9.6

lxml: 3.7.3

bs4: 4.6.0

html5lib: 0.9999999

sqlalchemy: 1.1.9

pymysql: None

psycopg2: None

jinja2: 2.9.6

s3fs: None

fastparquet: None

pandas_gbq: None

pandas_datareader: 0.5.0

``tokenizer.decode(response_ids, skip_special_tokens=True)``

``TypeError: decode() got an unexpected keyword argument 'skip_special_tokens'``

icinga2_feature

CACHE_PLUGIN_CONNECTION(/home/ansible/ansible/ansible.cfg) = ~/.cache/

DEFAULT_MANAGED_STR(/home/ansible/ansible/ansible.cfg) = Ansible managed file, do not edit directly

DEFAULT_REMOTE_USER(/home/ansible/ansible/ansible.cfg) = ansible

  File "/usr/lib/python2.7/re.py", line 146, in search

  File "/usr/lib/python2.7/re.py", line 146, in search

  File "/usr/lib/python2.7/re.py", line 146, in search

Error connecting to HomematicIP with HAP XYZ. Retrying in 16 seconds

Error connecting to HomematicIP with HAP XYZ. Retrying in 32 seconds

Error connecting to HomematicIP with HAP XYZ. Retrying in 64 seconds

Error connecting to HomematicIP with HAP XYZ. Retrying in 128 seconds

Error connecting to HomematicIP with HAP XYZ. Retrying in 256 seconds

daikin

  File "/Library/Frameworks/Python.framework/Versions/2.7/lib/python2.7/site-packages/pandas-0.11.0-py2.7-macosx-10.6-intel.egg/pandas/util/testing.py", line 250, in assert_frame_equal

  File "/Library/Frameworks/Python.framework/Versions/2.7/lib/python2.7/site-packages/pandas-0.11.0-py2.7-macosx-10.6-intel.egg/pandas/util/testing.py", line 250, in assert_frame_equal

  File "/Library/Frameworks/Python.framework/Versions/2.7/lib/python2.7/site-packages/pandas-0.11.0-py2.7-macosx-10.6-intel.egg/pandas/util/testing.py", line 250, in assert_frame_equal

  File "/Library/Frameworks/Python.framework/Versions/2.7/lib/python2.7/site-packages/pandas-0.11.0-py2.7-macosx-10.6-intel.egg/pandas/util/testing.py", line 249, in assert_frame_equal

  File "/Library/Frameworks/Python.framework/Versions/2.7/lib/python2.7/site-packages/pandas-0.11.0-py2.7-macosx-10.6-intel.egg/pandas/util/testing.py", line 249, in assert_frame_equal

  File "/Library/Frameworks/Python.framework/Versions/2.7/lib/python2.7/site-packages/pandas-0.11.0-py2.7-macosx-10.6-intel.egg/pandas/util/testing.py", line 250, in assert_frame_equal

  File "/Library/Frameworks/Python.framework/Versions/2.7/lib/python2.7/site-packages/pandas-0.11.0-py2.7-macosx-10.6-intel.egg/pandas/util/testing.py", line 250, in assert_frame_equal

/Library/Frameworks/Python.framework/Versions/2.7/lib/python2.7/site-packages/pandas-0.11.0-py2.7-macosx-10.6-intel.egg/pandas/tests$

0x00007ffff6252acf in ?? () from /usr/lib/pymodules/python2.6/numpy/core/umath.so

ValueError: ['b' 'a' 'r'] not contained in the index

INSTALLED VERSIONS

commit: None

python: 3.5.1.final.0

python-bits: 64

OS: Linux

OS-release: 4.4.6-gnu-1

machine: x86_64

processor:

byteorder: little

LC_ALL: None

LANG: en_DK.UTF-8

pandas: 0.18.0

nose: 1.3.7

pip: 8.1.1

setuptools: 18.2

Cython: 0.24

numpy: 1.11.0

scipy: 0.17.0

statsmodels: None

xarray: None

IPython: 4.1.2

sphinx: 1.4

patsy: None

dateutil: 2.5.2

pytz: 2016.3

blosc: None

bottleneck: None

tables: 3.2.2

numexpr: 2.5.2

matplotlib: 1.5.1

openpyxl: None

xlrd: 0.9.4

xlwt: None

xlsxwriter: None

lxml: None

bs4: 4.4.1

html5lib: None

httplib2: 0.9.2

apiclient: 1.5.0

sqlalchemy: 1.0.12

pymysql: None

psycopg2: 2.6.1 (dt dec pq3 ext lo64)

jinja2: 2.8

boto: None

touch file

cat buggy.yml

core-ssh:~# hassio ha info

arch: amd64

boot: true

image: homeassistant/qemux86-64-homeassistant

ip_address: 172.30.32.1

last_version: 0.94.1

machine: qemux86-64

foobot:

core-2021.4.3

cat temp.csv

a,c

b,d

,

a,c

b,d

INSTALLED VERSIONS

commit: None

python: 3.5.1.final.0

python-bits: 64

OS: Linux

OS-release: 4.5.2-gnu-1

machine: x86_64

processor:

byteorder: little

LC_ALL: None

LANG: en_DK.UTF-8

pandas: 0.18.0

nose: 1.3.7

pip: 8.1.1

setuptools: 20.10.1

Cython: 0.24

numpy: 1.11.0

scipy: 0.17.0

statsmodels: None

xarray: None

IPython: 4.2.0

sphinx: 1.4

patsy: None

dateutil: 2.5.3

pytz: 2016.4

blosc: None

bottleneck: None

tables: 3.2.2

numexpr: 2.5.2

matplotlib: 1.5.1

openpyxl: None

xlrd: 0.9.4

xlwt: None

xlsxwriter: None

lxml: None

bs4: 4.4.1

html5lib: None

httplib2: 0.9.2

apiclient: 1.5.0

sqlalchemy: 1.0.12

pymysql: None

psycopg2: 2.6.1 (dt dec pq3 ext lo64)

jinja2: 2.8

boto: None

error: cannot format demo.py: INTERNAL ERROR: Black produced code that is not equivalent to the source.  Please report a bug on https://github.com/psf/black/issues.  This diff might be helpful: /tmp/blk__7di9438.log

Operating System

HassOS 4.15

Supervisor

Newest Version

arch	x86_64

chassis	embedded

docker	true

docker_version	19.03.11

hassio	true

host_os	HassOS 4.15

installation_type	Home Assistant OS

os_name	Linux

os_version	5.4.72

python_version	3.8.6

supervisor	2020.10.0

version	0.117.0b6

virtualenv	false

Lovelace

mode	storage

resources	1

docs.ansible.com

commit: None

python: 3.5.1.final.0

python-bits: 64

OS: Darwin

OS-release: 15.5.0

machine: x86_64

processor: i386

byteorder: little

LC_ALL: None

LANG: de_DE.UTF-8

pandas: 0.18.1

nose: 1.3.7

pip: 8.1.2

setuptools: 20.3

Cython: 0.23.4

numpy: 1.10.4

scipy: 0.17.1

statsmodels: 0.6.1

xarray: None

IPython: 4.2.0

sphinx: 1.3.5

patsy: 0.4.0

dateutil: 2.5.1

pytz: 2016.2

blosc: None

bottleneck: 1.0.0

tables: 3.2.2

numexpr: 2.5.2

matplotlib: 1.5.1

openpyxl: 2.3.2

xlrd: 0.9.4

xlwt: 1.0.0

xlsxwriter: 0.8.4

lxml: 3.6.0

bs4: 4.4.1

html5lib: None

httplib2: None

apiclient: None

sqlalchemy: 1.0.12

pymysql: None

psycopg2: None

jinja2: 2.8

boto: 2.39.0

pandas_datareader: 0.2.1

`repr(request)` raises

udp        0      0 0.0.0.0:5353            0.0.0.0:*                           970/avahi-daemon: r

udp        0      0 127.0.0.1:8125          0.0.0.0:*                           27001/netdata

udp        0      0 0.0.0.0:631             0.0.0.0:*                           12702/cups-browsed

iosxr_command

communicate

Connection

Ubuntu 18.04.1 LTS

- name: "PLAY 1"

topics/contributing/

PATH invaild

module `dynamodb_table`

Pipenv version: `'2018.10.9'`

Pipenv location: `'/home/kubuntu/.local/lib/python3.7/site-packages/pipenv'`

Python location: `'/usr/bin/python3.7'`

Python installations found:

  - `3.7.0`: `/home/kubuntu/.local/share/virtualenvs/simple-v0MobB9A/bin/python3.7m`

  - `3.7.0`: `/usr/bin/python3.7m`

  - `3.7.0`: `/usr/bin/python3.7`

  - `3.6.6`: `/usr/bin/python3.6`

  - `3.6.6`: `/usr/bin/python3.6m`

  - `2.7.15rc1`: `/usr/bin/python2.7`

PEP 508 Information:

 - `PIPENV_ACTIVE`: `1`

  - `PATH`: `/home/kubuntu/.local/share/virtualenvs/simple-v0MobB9A/bin:/home/kubuntu/.local/bin:/home/kubuntu/.local/bin:/usr/local/sbin:/usr/local/bin:/usr/sbin:/usr/bin:/sbin:/bin:/usr/games:/usr/local/games`

  - `SHELL`: `/usr/bin/zsh`

  - `EDITOR`: `nano`

  - `LANG`: `en_US.UTF-8`

  - `PWD`: `/home/kubuntu/work/playground/django/simple`

  - `VIRTUAL_ENV`: `/home/kubuntu/.local/share/virtualenvs/simple-v0MobB9A`

(simple-v0MobB9A) machine42 ➜  simple git:(master) ✗

(simple)machine42 ➜  simple git:(master) ✗

keras_version: 2.0.4

x: Series | DataFrame

[0K

Your build has been stopped.

[windows]

ansible -i inventory windows -m win_ping

ansible -i inventories/inventory windows -m win_ping

<!--- Paste verbatim command output between quotes below -->

**POST**

**GET**

@tornado.web.asynchronous

virtualenv

http.client.RemoteDisconnected: Remote end closed connection without response

requests.exceptions.ConnectionError: ('Connection aborted.', RemoteDisconnected('Remote end closed connection without response'))

Updating state for switch.juha_ipad_pro (<class 'homeassistant.components.unifi.switch.UniFiBlockClientSwitch'>) took 3.050 seconds. Please create a bug report at https://github.com/home-assistant/core/issues?q=is%3Aopen+is%3Aissue+label%3A%22integration%3A+unifi%22

INSTALLED VERSIONS

commit           : None

python           : 3.8.3.final.0

python-bits      : 64

OS               : Linux

OS-release       : 5.7.7-arch1-1

machine          : x86_64

processor        :

byteorder        : little

LC_ALL           : None

LANG             : en_FYL.UTF-8

LOCALE           : en_US.UTF-8

pandas           : 1.0.5

numpy            : 1.19.0

pytz             : 2020.1

dateutil         : 2.8.1

pip              : 20.1.1

setuptools       : 49.1.0

Cython           : None

pytest           : None

hypothesis       : None

sphinx           : None

blosc            : None

feather          : None

xlsxwriter       : None

lxml.etree       : 4.5.1

html5lib         : 1.1

pymysql          : None

psycopg2         : None

jinja2           : 2.11.2

IPython          : 7.16.1

pandas_datareader: None

bs4              : 4.9.1

bottleneck       : None

fastparquet      : None

gcsfs            : None

lxml.etree       : 4.5.1

matplotlib       : 3.2.2

numexpr          : None

odfpy            : None

openpyxl         : None

pandas_gbq       : None

pyarrow          : None

pytables         : None

pytest           : None

pyxlsb           : None

s3fs             : None

scipy            : 1.5.0

sqlalchemy       : 1.3.18

tables           : None

tabulate         : None

xarray           : None

xlrd             : None

xlwt             : None

xlsxwriter       : None

numba            : None

vmware_object_role_permission

Ansible 2.7.7 (Module was imported using import folder in AWX)

climate/generic_thermostat

This is what I get in the logs:

pip

Package            Version

charset-normalizer 2.0.7

requests           2.26.0

urllib3            1.26.7

Package            Version

charset-normalizer 2.0.7

requests           2.26.0

urllib3            1.26.7

Package    Version

setuptools 58.3.0

test_dag_1

test_dag_10

test_dag_2

test_dag_3

test_dag_1

test_dag_2

test_dag_3

test_dag_10

curl -v -m 20  http://127.0.0.1:8888

ios_user

content-language: en-US

content-encoding: identity

content-language: en-US

content-encoding: identity

- LocalStack:

localstack-client        1.26

ecs_taskdefinition

CASSANDRA_SERVERS

CASSANDRA_KEYSPACE

CASSANDRA_TABLE

CASSANDRA_READ_CONSISTENCY

CASSANDRA_WRITE_CONSISTENCY

CASSANDRA_ENTRY_TTL

win_iis_virtualdirectory

Resolving dependencies...

Complete output (57 lines):

  Getting requirements to build wheel: started

Building wheels for collected packages: maturin

ERROR: Could not build wheels for maturin which use PEP 517 and cannot be installed directly

  File "/private/tmp/platform-venv/lib/python3.9/site-packages/pipenv/resolver.py", line 764, in <module>

  File "/private/tmp/platform-venv/lib/python3.9/site-packages/pipenv/resolver.py", line 758, in main

  File "/private/tmp/platform-venv/lib/python3.9/site-packages/pipenv/resolver.py", line 702, in resolve_packages

  File "/private/tmp/platform-venv/lib/python3.9/site-packages/pipenv/resolver.py", line 684, in resolve

  File "/private/tmp/platform-venv/lib/python3.9/site-packages/pipenv/patched/notpip/_internal/legacy_resolve.py", line 339, in _resolve_one

  File "/private/tmp/platform-venv/lib/python3.9/site-packages/pipenv/patched/notpip/_internal/legacy_resolve.py", line 287, in _get_abstract_dist_for

  File "/private/tmp/platform-venv/lib/python3.9/site-packages/pipenv/patched/notpip/_internal/distributions/sdist.py", line 38, in prepare_distribution_metadata

  File "/private/tmp/platform-venv/lib/python3.9/site-packages/pipenv/patched/notpip/_internal/distributions/sdist.py", line 66, in _setup_isolation

  File "/private/tmp/platform-venv/lib/python3.9/site-packages/pipenv/patched/notpip/_internal/build_env.py", line 202, in install_requirements

  File "/private/tmp/platform-venv/lib/python3.9/site-packages/pipenv/patched/notpip/_internal/utils/subprocess.py", line 242, in call_subprocess

  File "main.py", line 225, in <module>

  File "main.py", line 38, in __init__

  File "main.py", line 44, in start_flask

# To run this, you need a Raspberry Pi 2 (or greater) with face_recognition and

  platform: modbus

in Holding Register 0000000000000011 is swith1 on and switch2 on

in Holding Register 0000000000000010 is swith1 off and switch2 on

  platform: modbus

byte_values = numpy.packbits(data)

data = numpy.random.sample(1024)

pi@hassbian:~ $ sudo hassbian-config install homeassistant

Home Assistant install script for Hassbian.

Copyright(c) 2017 Fredrik Lindqvist <https://github.com/Landrash>.

Changing to the homeassistant user

Creating Home Assistant venv

Changing to Home Assistant venv

Installing latest version of Home Assistant

  Downloading https://www.piwheels.org/simple/cryptography/cryptography-2.3.1-cp35-cp35m-linux_armv6l.whl (820kB)

  File "/usr/lib/python3.5/http/client.py", line 1198, in getresponse

http.client.RemoteDisconnected: Remote end closed connection without response

TypeError: unsupported operand type(s) for -=: 'Retry' and 'int'

Deactivating virtualenv

Enabling Home Assistant service

Disabling the Home Assistant install script

Starting Home Assistant

Checking the installation...

Installation failed...

If you have issues with this script, please say something in the #devs_hassbian channel on Discord.

pi@hassbian:~ $

INSTALLED VERSIONS

commit: None

python: 2.7.12.final.0

python-bits: 64

OS: Linux

OS-release: 4.15.0-32-generic

machine: x86_64

processor: x86_64

byteorder: little

LC_ALL: None

LANG: en_US.UTF-8

LOCALE: None.None

pandas: 0.23.3

pytest: None

pip: 18.0

setuptools: 20.7.0

Cython: None

numpy: 1.15.0

scipy: None

pyarrow: None

xarray: None

IPython: 5.8.0

sphinx: None

patsy: None

dateutil: 2.7.3

pytz: 2018.5

blosc: None

bottleneck: None

tables: None

numexpr: None

feather: None

matplotlib: None

openpyxl: None

xlrd: 1.1.0

xlwt: None

xlsxwriter: 1.0.5

lxml: None

bs4: None

html5lib: None

sqlalchemy: None

pymysql: None

psycopg2: None

jinja2: None

s3fs: None

fastparquet: None

pandas_gbq: None

pandas_datareader: None

function1

function2

win_unzip

`ansible-config dump --only-changed` returns nothing.

df_result

INSTALLED VERSIONS

commit: 2f4d393d6e0b7cfeed0691c3230ea6ece418bb20

python: 3.6.5.final.0

python-bits: 64

OS: Windows

OS-release: 7

machine: AMD64

processor: Intel64 Family 6 Model 62 Stepping 4, GenuineIntel

byteorder: little

LC_ALL: None

LANG: None

LOCALE: None.None

pandas: 0.24.0.dev0+113.g263386389

pytest: 3.6.0

pip: 10.0.1

setuptools: 39.2.0

Cython: 0.28.3

numpy: 1.14.2

scipy: 1.0.0

pyarrow: 0.8.0

xarray: 0.10.6

IPython: 6.4.0

sphinx: 1.7.5

patsy: 0.5.0

dateutil: 2.7.3

pytz: 2018.4

blosc: None

bottleneck: 1.2.1

tables: 3.4.3

numexpr: 2.6.4

feather: 0.4.0

matplotlib: 2.2.2

openpyxl: 2.5.3

xlrd: 1.1.0

xlwt: 1.3.0

xlsxwriter: 1.0.5

lxml: 4.1.1

bs4: 4.6.0

html5lib: 1.0.1

sqlalchemy: 1.2.8

pymysql: 0.8.1

psycopg2: None

jinja2: 2.10

s3fs: 0.1.5

fastparquet: 0.1.5

pandas_gbq: None

pandas_datareader: None

august:

ozw log:

 10   <!-- If you are using any Security Devices, you MUST set a network Key -->

 13   <!-- Some Devices have a big UserCode Table, that can mean startup times

debug log:

arch | x86_64

chassis | vm

dev | false

docker | true

docker_version | 19.03.8

hassio | true

host_os | HassOS 4.10

installation_type | Home Assistant OS

os_name | Linux

os_version | 5.4.44

python_version | 3.7.7

supervisor | 227

timezone | Europe/Amsterdam

version | 0.112.0

virtualenv | false

  File "/Users/xxxx/Dropbox (Seatgeek)/ansible/lib/ansible/playbook/__init__.py", line 53, in load

  File "/Users/xxxx/Dropbox (Seatgeek)/ansible/lib/ansible/playbook/__init__.py", line 91, in _load_playbook_data

  File "/Users/xxxx/Dropbox (Seatgeek)/ansible/lib/ansible/playbook/block.py", line 72, in load

http://stackoverflow.com/questions/21318865/read-multi-index-on-the-columns-from-csv-file

1. ansible-vault existing_vault.yml

Step 44/3000 - 0.31283405731719177 steps/s

  warnings.warn(self.msg_depr % (key, alt_key))

  warnings.warn(self.msg_depr % (key, alt_key))

  "is being cleared", UserWarning)

axes property.  A removal date has not been set.

  warnings.warn(_get_axes_msg, mplDeprecation, stacklevel=1)

- (0.0, 0.0, 1.0, 1.0)

Error:

df_grp.count()

Pipenv version: `'2018.11.26'`

Pipenv location: `'/usr/local/Cellar/pipenv/2018.11.26_4/libexec/lib/python3.8/site-packages/pipenv'`

Python location: `'/usr/local/Cellar/pipenv/2018.11.26_4/libexec/bin/python3.8'`

Python installations found:

  - `3.8.2`: `/Users/tianyizhuang/.local/share/virtualenvs/dapeng-ojERrZnV/bin/python3`

  - `3.7.7`: `/usr/local/bin/python3`

  - `3.7.7`: `/usr/local/bin/python3.7m`

  - `3.7.3`: `/usr/bin/python3`

  - `2.7.17`: `/usr/local/bin/python`

  - `2.7.17`: `/usr/local/bin/pythonw`

  - `2.7.16`: `/usr/bin/python`

  - `2.7.16`: `/usr/bin/pythonw`

PEP 508 Information:

System environment variables:

Pipenv–specific environment variables:

 - `PIPENV_ACTIVE`: `1`

Debug–specific environment variables:

  - `PATH`: `/usr/local/Cellar/pipenv/2018.11.26_4/libexec/tools:/Users/tianyizhuang/.local/share/virtualenvs/dapeng-ojERrZnV/bin:/Users/tianyizhuang/.tiup/bin:/usr/local/opt/python@3.8/bin:/Users/tianyizhuang/go/bin:/Users/tianyizhuang/.cargo/bin:/usr/local/Cellar/pipenv/2018.11.26_4/libexec/tools:/Users/tianyizhuang/.tiup/bin:/usr/local/opt/python@3.8/bin:/Users/tianyizhuang/go/bin:/Users/tianyizhuang/.cargo/bin:/Users/tianyizhuang/.cargo/bin:/usr/local/bin:/usr/bin:/bin:/usr/sbin:/sbin:/usr/local/opt/riscv-gnu-toolchain/bin:/usr/local/opt/fzf/bin:/usr/local/opt/riscv-gnu-toolchain/bin`

  - `SHELL`: `/bin/zsh`

  - `PWD`: `/Users/tianyizhuang/Projects/dapeng`

  - `VIRTUAL_ENV`: `/Users/tianyizhuang/.local/share/virtualenvs/dapeng-ojERrZnV`

Contents of `Pipfile` ('/Users/tianyizhuang/Projects/dapeng/Pipfile'):

mypy = "*"

Contents of `Pipfile.lock` ('/Users/tianyizhuang/Projects/dapeng/Pipfile.lock'):

# TODO: Update this line to work with batch > 1. Right now it assumes all

**input shape: (nb_samples, 32)**

nxos_l3_interface

<!--- Paste example playbooks or commands between quotes below -->

TemplateSyntaxError: Encountered unknown tag 'do'. Jinja was looking for the following tags: 'elif' or 'else' or 'endif'. The innermost block that needs to be closed is 'if'.

venv

2. Run `python run_glue.py --model_name_or_path roberta-large --do_train --do_eval --per_gpu_train_batch_size 8 --output_dir hypersearch-0 --task_name sst2 --evaluation_strategy steps --eval_steps 20 --logging_steps 10`

  File "/home/howard/anaconda3/envs/transformers/lib/python3.8/site-packages/ray/tune/registry.py", line 71, in register_trainable

  File "/home/howard/anaconda3/envs/transformers/lib/python3.8/site-packages/ray/tune/registry.py", line 124, in register

  File "/home/howard/anaconda3/envs/transformers/lib/python3.8/site-packages/ray/tune/registry.py", line 146, in flush_values

  File "/usr/local/lib/python3.6/site-packages/numpy/__init__.py", line 126, in <module>

  File "/usr/local/lib/python3.6/site-packages/numpy/__config__.py", line 9, in <module>

Value Error: Can't fit matrix with Nans or Infinities

removing 'ansible-2.0.0.1' (and everything under it)

error: line 10: Illegal sequence ".." in: Release: 0.git201601130000...el7.centos